Workbook

Sheet README
B1: VPS Hosting Financial Model
B3: PURPOSE | C3: Model startup cost, monthly operating cost, break-even, and revenue for 3, 5, and 10 node Proxmox+Ceph clusters.
B5: HOW TO USE | C5: Edit only BLUE cells and YELLOW-filled cells. Everything black is a formula and will recalculate.
C6: Start on 'Assumptions'. Every figure there is an input you should replace with a real quote.
B8: IMPORTANT | C8: All default cost figures are INDICATIVE PLACEHOLDERS, not quotes.
C9: They came from the assistant's training data (knowledge cutoff May 2026) and vary enormously by
C10: region, vendor, new vs refurbished, and market conditions. IPv4 and RAM pricing in particular move a lot.
C11: Replace every one with a real quote before making any decision based on this model.
B13: NOT ADVICE | C13: This is a calculation tool, not financial advice. The assistant that built it is not a licensed
C14: financial advisor. Have an accountant review your assumptions and the resulting plan.
B16: COLOR LEGEND
B17: Blue text | C17: Hardcoded input you should edit
B18: Yellow fill | C18: Key assumption - edit this
B19: Black text | C19: Formula - do not edit
B20: Green text | C20: Link to another sheet
B22: SHEETS
B23: Assumptions | C23: All inputs. Edit here.
B24: Capacity | C24: Derives VMs per node from the plan mix. Identifies the binding resource.
B25: Startup Costs | C25: One-time capex and setup cost by cluster size.
B26: Monthly Opex | C26: Recurring cost by cluster size.
B27: Revenue & Pricing | C27: Plan catalogue, ARPU, revenue at target utilisation.
B28: Break-Even | C28: Break-even VM count and utilisation by cluster size.
B29: Scenarios | C29: Side-by-side 3 / 5 / 10 node comparison.
B30: Cash Flow 24mo | C30: Monthly cash flow with a ramp assumption.

Sheet Assumptions
A1: Assumptions - edit blue / yellow cells only
A2: All cost defaults are indicative placeholders. Replace with real quotes.
A4: Assumption | B4: Value | C4: Unit | D4: Note / source
A5: HARDWARE - PER NODE (capex)
A6: Compute node cost | B6: 14000 | C6: $ | D6: Single-socket EPYC, 512GB RAM, 6x7.68TB NVMe PLP, 2x25GbE, redundant PSU. Refurb prior-gen roughly halves this.
A7: Installed RAM per node | B7: 512 | C7: GB | D7: See Phase 2: RAM is usually the binding resource.
A8: CPU threads per node | B8: 128 | C8: threads | D8: 64-core single socket EPYC.
A9: NVMe drives per node | B9: 6 | C9: drives
A10: Raw TB per drive | B10: 7.68 | C10: TB
A11: Reserved RAM per node | B11: 48 | C11: GB | D11: 6 OSDs x 6GB + 4GB ZFS ARC + 8GB host. Not sellable.
A12: SHARED INFRASTRUCTURE (capex, one-time)
A13: Backup server (PBS) + capacity | B13: 9000 | C13: $ | D13: Must be separate physical hardware.
A14: Switches (2x 25GbE) | B14: 12000 | C14: $ | D14: Pair, with MLAG. Refurb prior-gen roughly 2000-5000 each.
A15: Border routers (2x) | B15: 6000 | C15: $ | D15: Software routing on x86 with FRR/VyOS is the budget option.
A16: Rack rails, PDUs, cables, optics | B16: 3500 | C16: $ | D16: Easy to underestimate. Add 10% contingency.
A17: Spares kit | B17: 3000 | C17: $ | D17: 1-2 NVMe, optics, PSU, boot SSD, fan.
A18: Monitoring host | B18: 2500 | C18: $ | D18: Must run OUTSIDE the production cluster.
A19: SETUP AND PROFESSIONAL COSTS (one-time)
A20: Legal - policy drafting and review | B20: 4000 | C20: $ | D20: AUP, ToS, SLA, Privacy, DPA, DMCA. Hosting/telecoms-experienced lawyer.
A21: Company formation and registration | B21: 1200 | C21: $ | D21: Varies enormously by jurisdiction.
A22: LIR sign-up fee (one-time) | B22: 2200 | C22: $ | D22: RIPE-style one-time fee. VERIFY current RIR fee schedule.
A23: IPv4 /24 purchase (if buying) | B23: 11000 | C23: $ | D23: 256 addresses at ~43 each. Market price moves a lot - get broker quotes.
A24: Colo deposit / installation | B24: 2500 | C24: $ | D24: Often 1-2 months rent as deposit.
A25: Cross-connect installation (one-time) | B25: 1500 | C25: $ | D25: Per-connection NRC, several needed.
A26: Contingency | B26: 0.12 | C26: % of capex | D26: Things you have not thought of. Do not set below 10%.
A27: MONTHLY OPERATING COSTS
A28: Colo - per rack unit equivalent | B28: 900 | C28: $/mo | D28: Quarter/half rack incl. power. CHECK whether power is billed separately.
A29: Colo cost scales at node count | B29: 6 | C29: nodes/rack-block | D29: How many nodes before you need another rack block.
A30: IP transit - both providers | B30: 1400 | C30: $/mo | D30: 2 providers, committed bandwidth + port fees. Get real quotes.
A31: Cross-connects recurring | B31: 400 | C31: $/mo | D31: Recurring, per connection. Adds up.
A32: IPv4 lease cost per address | B32: 0.7 | C32: $/IP/mo | D32: If leasing rather than buying. Market range roughly 0.50-1.00.
A33: DDoS scrubbing | B33: 700 | C33: $/mo | D33: Set to 0 for blackhole-only posture (must be disclosed in SLA).
A34: Proxmox subscription per node | B34: 32 | C34: $/node/mo | D34: Per socket per node, annual fee divided by 12. VERIFY current pricing.
A35: PBS subscription | B35: 32 | C35: $/mo
A36: LIR annual membership (monthly) | B36: 145 | C36: $/mo | D36: Annual RIR membership / 12. VERIFY current fee schedule.
A37: Billing platform + Proxmox module | B37: 60 | C37: $/mo | D37: WHMCS/Blesta licence plus provisioning module.
A38: Monitoring / misc SaaS | B38: 80 | C38: $/mo | D38: Status page, SMS alerting, email delivery, DNS.
A39: Accounting and bookkeeping | B39: 350 | C39: $/mo
A40: Insurance | B40: 250 | C40: $/mo | D40: General liability, professional indemnity, cyber.
A41: Founder / staff cost | B41: 0 | C41: $/mo | D41: Set to 0 for an unpaid founder, or enter a real salary cost.
...

Sheet Capacity
A1: Capacity - derive VMs per node from the plan mix (3-node reference)
A2: The binding resource is whichever gives the LOWEST VM count. Size from this, not from the spec sheet.
A4: PLAN MIX - edit the blue weight and spec columns
A5: Plan | B5: Weight % | C5: vCPU | D5: RAM GB | E5: Disk GB | F5: IPv4 | G5: Price $/mo | H5: Note
A6: S1 | B6: 0.2 | C6: 1 | D6: 2 | E6: 40 | F6: 1 | G6: 8
A7: S2 | B7: 0.35 | C7: 2 | D7: 4 | E7: 80 | F7: 1 | G7: 15
A8: S4 | B8: 0.25 | C8: 4 | D8: 8 | E8: 160 | F8: 1 | G8: 29
A9: S8 | B9: 0.15 | C9: 8 | D9: 16 | E9: 320 | F9: 1 | G9: 58
A10: S16 | B10: 0.05 | C10: 16 | D10: 32 | E10: 640 | F10: 1 | G10: 115
A11: Total / weighted average | B11: =SUM(B6:B10) -> 1 | C11: =SUMPRODUCT($B$6:$B$10,C6:C10)/$B$11 -> 3.9 | D11: =SUMPRODUCT($B$6:$B$10,D6:D10)/$B$11 -> 7.8 | E11: =SUMPRODUCT($B$6:$B$10,E6:E10)/$B$11 -> 156 | F11: =SUMPRODUCT($B$6:$B$10,F6:F10)/$B$11 -> 1 | G11: =SUMPRODUCT($B$6:$B$10,G6:G10)/$B$11 -> 28.55 | H11: Weights must sum to 100%. ARPU is column G.
A13: CAPACITY PER NODE BY RESOURCE
A14: Resource | B14: Available | C14: Per VM | D14: VMs/node | H14: Note
A15: RAM | B15: =Assumptions!B7-Assumptions!B11 -> 464 | C15: =D11 -> 7.8 | D15: =IF(C15=0,0,B15/C15) -> 59.487179 | H15: Installed minus reserved for OSDs, ARC, host. Do NOT overcommit RAM.
A16: vCPU (at overcommit) | B16: =Assumptions!B8*B18 -> 448 | C16: =C11 -> 3.9 | D16: =IF(C16=0,0,B16/C16) -> 114.87179 | H16: Threads x overcommit ratio below.
A17: Disk (Ceph, per node share) | B17: =Assumptions!B9*Assumptions!B10*1000/3*B19 -> 9216 | C17: =E11 -> 156 | D17: =IF(C17=0,0,B17/C17) -> 59.076923 | H17: Raw TB per node / replica 3 x safety factor. GB.
A18: vCPU overcommit ratio | B18: 3.5 | H18: 3:1 to 4:1 standard shared tier. Monitor CPU steal time.
A19: Ceph safety factor (3 nodes) | B19: 0.6 | H19: 0.60 on 3 nodes (cannot self-heal), 0.70 at 5, 0.75 at 6+.
A21: BINDING RESOURCE
A22: VMs per node (binding) | B22: =MIN(D15,D16,D17) -> 59.076923 | H22: 3-node reference. Revenue & Pricing recomputes this per cluster size.
A23: Binding resource is | B23: =IF(B22=D15,"RAM",IF(B22=D16,"vCPU","Disk")) -> Disk | H23: Buy more of this resource to increase density.
A24: ARPU (weighted avg revenue per VM) | B24: =G11 -> 28.55

Sheet Startup Costs
A1: Startup Costs (one-time) by cluster size
A3: Cost item | B3: 3 nodes | C3: 5 nodes | D3: 10 nodes | E3: Note
A4: Node count | B4: 3 | C4: 5 | D4: 10 | E4: Cluster size scenarios.
A6: CAPEX
A7: Compute nodes | B7: =Assumptions!$B$6*3 -> 42000 | C7: =Assumptions!$B$6*5 -> 70000 | D7: =Assumptions!$B$6*10 -> 140000 | E7: Scales with node count.
A8: Backup server (PBS) | B8: =Assumptions!$B$13 -> 9000 | C8: =Assumptions!$B$13 -> 9000 | D8: =Assumptions!$B$13 -> 9000 | E8: One, regardless of cluster size at this scale.
A9: Switches | B9: =Assumptions!$B$14*IF(3>24,2,1) -> 12000 | C9: =Assumptions!$B$14*IF(5>24,2,1) -> 12000 | D9: =Assumptions!$B$14*IF(10>24,2,1) -> 12000 | E9: One pair up to ~24 nodes.
A10: Border routers | B10: =Assumptions!$B$15 -> 6000 | C10: =Assumptions!$B$15 -> 6000 | D10: =Assumptions!$B$15 -> 6000 | E10: Pair.
A11: Rails, PDUs, cables, optics | B11: =Assumptions!$B$16*3/3 -> 3500 | C11: =Assumptions!$B$16*5/3 -> 5833.3333 | D11: =Assumptions!$B$16*10/3 -> 11666.667 | E11: Scales roughly with node count.
A12: Spares kit | B12: =Assumptions!$B$17 -> 3000 | C12: =Assumptions!$B$17 -> 3000 | D12: =Assumptions!$B$17 -> 3000 | E12: Grows slowly; one kit covers a small cluster.
A13: Monitoring host | B13: =Assumptions!$B$18 -> 2500 | C13: =Assumptions!$B$18 -> 2500 | D13: =Assumptions!$B$18 -> 2500 | E13: Outside the cluster.
A14: Subtotal capex (hardware) | B14: =SUM(B7:B13) -> 78000 | C14: =SUM(C7:C13) -> 108333.33 | D14: =SUM(D7:D13) -> 184166.67
A16: SETUP AND PROFESSIONAL
A17: Legal - policies and review | B17: =Assumptions!$B$20 -> 4000 | C17: =Assumptions!$B$20 -> 4000 | D17: =Assumptions!$B$20 -> 4000 | E17: AUP, ToS, SLA, Privacy, DPA, DMCA.
A18: Company formation | B18: =Assumptions!$B$21 -> 1200 | C18: =Assumptions!$B$21 -> 1200 | D18: =Assumptions!$B$21 -> 1200
A19: LIR sign-up fee | B19: =Assumptions!$B$22 -> 2200 | C19: =Assumptions!$B$22 -> 2200 | D19: =Assumptions!$B$22 -> 2200 | E19: One-time. VERIFY current RIR schedule.
A20: IPv4 purchase (if buying) | B20: =IF(Assumptions!$B$50=1,CEILING(Capacity!$B$22*3*Assumptions!$B$49/250,1)*Assumptions!$B$23,0) -> 11000 | C20: =IF(Assumptions!$B$50=1,CEILING(Capacity!$B$22*5*Assumptions!$B$49/250,1)*Assumptions!$B$23,0) -> 22000 | D20: =IF(Assumptions!$B$50=1,CEILING(Capacity!$B$22*10*Assumptions!$B$49/250,1)*Assumptions!$B$23,0) -> 33000 | E20: Only if 'Buy IPv4' flag = 1. Scales with VM capacity.
A21: Colo deposit / install | B21: =Assumptions!$B$24 -> 2500 | C21: =Assumptions!$B$24 -> 2500 | D21: =Assumptions!$B$24 -> 2500
A22: Cross-connect install | B22: =Assumptions!$B$25 -> 1500 | C22: =Assumptions!$B$25 -> 1500 | D22: =Assumptions!$B$25 -> 1500
A23: Subtotal setup | B23: =SUM(B17:B22) -> 22400 | C23: =SUM(C17:C22) -> 33400 | D23: =SUM(D17:D22) -> 44400
A25: Contingency | B25: =(B14+B23)*Assumptions!$B$26 -> 12048 | C25: =(C14+C23)*Assumptions!$B$26 -> 17008 | D25: =(D14+D23)*Assumptions!$B$26 -> 27428 | E25: Applied to hardware + setup.
A26: TOTAL STARTUP COST | B26: =B14+B23+B25 -> 112448 | C26: =C14+C23+C25 -> 158741.33 | D26: =D14+D23+D25 -> 255994.67
A28: Recommended cash reserve (see Cash Flow sheet)
A29: Total capital required incl. 12mo opex buffer | B29: =B26+'Monthly Opex'!B$100*12 -> 165404 | C29: =C26+'Monthly Opex'!C$100*12 -> 212465.33 | D29: =D26+'Monthly Opex'!D$100*12 -> 332518.67 | E29: Revenue ramps slowly. Model 18 months of runway, not 6.

Sheet Monthly Opex
A1: Monthly Operating Costs by cluster size
A3: Cost item | B3: 3 nodes | C3: 5 nodes | D3: 10 nodes | E3: Note
A4: Node count | B4: ='Startup Costs'!B4 -> 3 | C4: ='Startup Costs'!C4 -> 5 | D4: ='Startup Costs'!D4 -> 10
A6: INFRASTRUCTURE
A7: Colo (space + power) | B7: =Assumptions!$B$28*CEILING(3/Assumptions!$B$29,1) -> 900 | C7: =Assumptions!$B$28*CEILING(5/Assumptions!$B$29,1) -> 900 | D7: =Assumptions!$B$28*CEILING(10/Assumptions!$B$29,1) -> 1800 | E7: Check whether power is billed separately.
A8: IP transit (2 providers) | B8: =Assumptions!$B$30*IF(3>5,1.6,1) -> 1400 | C8: =Assumptions!$B$30*IF(5>5,1.6,1) -> 1400 | D8: =Assumptions!$B$30*IF(10>5,1.6,1) -> 2240 | E8: Scales in steps as commit increases.
A9: Cross-connects | B9: =Assumptions!$B$31 -> 400 | C9: =Assumptions!$B$31 -> 400 | D9: =Assumptions!$B$31 -> 400 | E9: Recurring. Easy to forget.
A10: IPv4 lease (if leasing) | B10: =IF(Assumptions!$B$50=0,Capacity!$B$22*3*Assumptions!$B$49*Assumptions!$B$32,0) -> 0 | C10: =IF(Assumptions!$B$50=0,Capacity!$B$22*5*Assumptions!$B$49*Assumptions!$B$32,0) -> 0 | D10: =IF(Assumptions!$B$50=0,Capacity!$B$22*10*Assumptions!$B$49*Assumptions!$B$32,0) -> 0 | E10: Zero if buying. Often the largest COGS line.
A11: DDoS scrubbing | B11: =Assumptions!$B$33 -> 700 | C11: =Assumptions!$B$33 -> 700 | D11: =Assumptions!$B$33 -> 700 | E11: Zero = blackhole-only posture, disclose in SLA.
A12: SOFTWARE AND SERVICES
A13: Proxmox subscriptions | B13: =Assumptions!$B$34*3 -> 96 | C13: =Assumptions!$B$34*5 -> 160 | D13: =Assumptions!$B$34*10 -> 320 | E13: Per socket per node. Single-socket keeps this low.
A14: PBS subscription | B14: =Assumptions!$B$35 -> 32 | C14: =Assumptions!$B$35 -> 32 | D14: =Assumptions!$B$35 -> 32
A15: LIR membership (monthly) | B15: =Assumptions!$B$36 -> 145 | C15: =Assumptions!$B$36 -> 145 | D15: =Assumptions!$B$36 -> 145 | E15: Annual fee / 12.
A16: Billing platform + module | B16: =Assumptions!$B$37 -> 60 | C16: =Assumptions!$B$37 -> 60 | D16: =Assumptions!$B$37 -> 60 | E16: Scales with client count on some licences.
A17: Monitoring / misc SaaS | B17: =Assumptions!$B$38 -> 80 | C17: =Assumptions!$B$38 -> 80 | D17: =Assumptions!$B$38 -> 80
A18: BUSINESS
A19: Accounting and bookkeeping | B19: =Assumptions!$B$39 -> 350 | C19: =Assumptions!$B$39 -> 350 | D19: =Assumptions!$B$39 -> 350
A20: Insurance | B20: =Assumptions!$B$40 -> 250 | C20: =Assumptions!$B$40 -> 250 | D20: =Assumptions!$B$40 -> 250
A21: Founder / staff cost | B21: =Assumptions!$B$41 -> 0 | C21: =Assumptions!$B$41 -> 0 | D21: =Assumptions!$B$41 -> 0
A22: NON-CASH
A23: Hardware depreciation | B23: ='Startup Costs'!B14/Assumptions!$B$43 -> 1625 | C23: ='Startup Costs'!C14/Assumptions!$B$43 -> 2256.9444 | D23: ='Startup Costs'!D14/Assumptions!$B$43 -> 3836.8056 | E23: Non-cash, but you must reserve for replacement.
A25: TOTAL CASH OPEX / MONTH | B25: =SUM(B7:B11)+SUM(B13:B17)+SUM(B19:B21) -> 4413 | C25: =SUM(C7:C11)+SUM(C13:C17)+SUM(C19:C21) -> 4477 | D25: =SUM(D7:D11)+SUM(D13:D17)+SUM(D19:D21) -> 6377
A26: TOTAL FULLY-LOADED / MONTH (incl. depreciation) | B26: =B25+B23 -> 6038 | C26: =C25+C23 -> 6733.9444 | D26: =D25+D23 -> 10213.806
A100: (helper: cash opex, referenced by Startup Costs) | B100: =B25 -> 4413 | C100: =C25 -> 4477 | D100: =D25 -> 6377

Sheet Revenue & Pricing
A1: Revenue and Pricing
A3: PRICING STRATEGY NOTE
A4: You cannot win on price against Hetzner or DigitalOcean - their scale is a structural advantage.
A5: Price at a premium and differentiate on: support quality, jurisdiction/data residency, a niche,
A6: or hardware nobody else offers. A price war you enter at 3 nodes is one you lose.
A7: The plan catalogue and prices are on the Capacity sheet - edit them there.
A9: Metric | B9: 3 nodes | C9: 5 nodes | D9: 10 nodes | E9: Note
A10: Node count | B10: ='Startup Costs'!B4 -> 3 | C10: ='Startup Costs'!C4 -> 5 | D10: ='Startup Costs'!D4 -> 10
A11: Ceph safety factor | B11: 0.6 | C11: 0.7 | D11: 0.75 | E11: 0.60 at 3 nodes, 0.70 at 5, 0.75 at 6+. Larger clusters can run fuller.
A12: VMs/node - RAM bound | B12: =(Assumptions!$B$7-Assumptions!$B$11)/Capacity!$D$11 -> 59.487179 | C12: =(Assumptions!$B$7-Assumptions!$B$11)/Capacity!$D$11 -> 59.487179 | D12: =(Assumptions!$B$7-Assumptions!$B$11)/Capacity!$D$11 -> 59.487179 | E12: Does not vary with cluster size.
A13: VMs/node - vCPU bound | B13: =Assumptions!$B$8*Capacity!$B$18/Capacity!$C$11 -> 114.87179 | C13: =Assumptions!$B$8*Capacity!$B$18/Capacity!$C$11 -> 114.87179 | D13: =Assumptions!$B$8*Capacity!$B$18/Capacity!$C$11 -> 114.87179 | E13: Does not vary with cluster size.
A14: VMs/node - disk bound | B14: =Assumptions!$B$9*Assumptions!$B$10*1000/3*B11/Capacity!$E$11 -> 59.076923 | C14: =Assumptions!$B$9*Assumptions!$B$10*1000/3*C11/Capacity!$E$11 -> 68.923077 | D14: =Assumptions!$B$9*Assumptions!$B$10*1000/3*D11/Capacity!$E$11 -> 73.846154 | E14: Varies with the safety factor above.
A15: VMs per node (binding resource) | B15: =MIN(B12,B13,B14) -> 59.076923 | C15: =MIN(C12,C13,C14) -> 59.487179 | D15: =MIN(D12,D13,D14) -> 59.487179 | E15: Minimum of the three above.
A16: Gross cluster VM capacity | B16: =B10*B15 -> 177.23077 | C16: =C10*C15 -> 297.4359 | D16: =D10*D15 -> 594.87179 | E16: nodes x VMs/node
A17: Less one node reserve (N+1) | B17: =-B15 -> -59.076923 | C17: =-C15 -> -59.487179 | D17: =-D15 -> -59.487179 | E17: Required for maintenance and failover. Not sellable.
A18: Sellable VM capacity | B18: =B16+B17 -> 118.15385 | C18: =C16+C17 -> 237.94872 | D18: =D16+D17 -> 535.38462 | E18: This is what you can actually sell.
A19: At target utilisation | B19: =B18*Assumptions!$B$47 -> 88.615385 | C19: =C18*Assumptions!$B$47 -> 178.46154 | D19: =D18*Assumptions!$B$47 -> 401.53846 | E19: Realistic steady-state VM count.
A20: ARPU per VM | B20: =Capacity!$B$24 -> 28.55 | C20: =Capacity!$B$24 -> 28.55 | D20: =Capacity!$B$24 -> 28.55 | E20: Weighted average from the plan mix.
A21: Gross monthly revenue at target | B21: =B19*B20 -> 2529.9692 | C21: =C19*C20 -> 5095.0769 | D21: =D19*D20 -> 11463.923
A22: Less payment processing | B22: =-B21*Assumptions!$B$44 -> -73.369108 | C22: =-C21*Assumptions!$B$44 -> -147.75723 | D22: =-D21*Assumptions!$B$44 -> -332.45377
A23: Less chargebacks / bad debt | B23: =-B21*Assumptions!$B$45 -> -37.949538 | C23: =-C21*Assumptions!$B$45 -> -76.426154 | D23: =-D21*Assumptions!$B$45 -> -171.95885
A24: Less SLA credits | B24: =-B21*Assumptions!$B$46 -> -12.649846 | C24: =-C21*Assumptions!$B$46 -> -25.475385 | D24: =-D21*Assumptions!$B$46 -> -57.319615
A25: NET MONTHLY REVENUE | B25: =SUM(B21:B24) -> 2406.0007 | C25: =SUM(C21:C24) -> 4845.4182 | D25: =SUM(D21:D24) -> 10902.191

Sheet Break-Even
A1: Break-Even Analysis
A3: Metric | B3: 3 nodes | C3: 5 nodes | D3: 10 nodes | E3: Note
A4: Cash opex per month | B4: ='Monthly Opex'!B25 -> 4413 | C4: ='Monthly Opex'!C25 -> 4477 | D4: ='Monthly Opex'!D25 -> 6377 | E4: Excludes depreciation.
A5: Fully-loaded cost per month | B5: ='Monthly Opex'!B26 -> 6038 | C5: ='Monthly Opex'!C26 -> 6733.9444 | D5: ='Monthly Opex'!D26 -> 10213.806 | E5: Includes depreciation reserve.
A6: ARPU per VM | B6: =Capacity!$B$24 -> 28.55 | C6: =Capacity!$B$24 -> 28.55 | D6: =Capacity!$B$24 -> 28.55
A7: Effective net revenue per VM | B7: =B6*(1-Assumptions!$B$44-Assumptions!$B$45-Assumptions!$B$46) -> 27.15105 | C7: =C6*(1-Assumptions!$B$44-Assumptions!$B$45-Assumptions!$B$46) -> 27.15105 | D7: =D6*(1-Assumptions!$B$44-Assumptions!$B$45-Assumptions!$B$46) -> 27.15105 | E7: ARPU less processing, bad debt, SLA credits.
A8: BREAK-EVEN VMs (cash) | B8: =IF(B7=0,0,B4/B7) -> 162.53515 | C8: =IF(C7=0,0,C4/C7) -> 164.89233 | D8: =IF(D7=0,0,D4/D7) -> 234.87121 | E8: VMs needed to cover cash costs.
A9: BREAK-EVEN VMs (fully loaded) | B9: =IF(B7=0,0,B5/B7) -> 222.38551 | C9: =IF(C7=0,0,C5/C7) -> 248.01783 | D9: =IF(D7=0,0,D5/D7) -> 376.18455 | E9: The number that matters. Includes hardware replacement reserve.
A10: Sellable VM capacity | B10: ='Revenue & Pricing'!B18 -> 118.15385 | C10: ='Revenue & Pricing'!C18 -> 237.94872 | D10: ='Revenue & Pricing'!D18 -> 535.38462
A11: Break-even as % of sellable capacity | B11: =IF(B10=0,0,B9/B10) -> 1.882169 | C11: =IF(C10=0,0,C9/C10) -> 1.0423163 | D11: =IF(D10=0,0,D9/D10) -> 0.70264356 | E11: ABOVE 60% MEANS YOUR PRICING IS WRONG.
A12: Net monthly revenue at target util | B12: ='Revenue & Pricing'!B25 -> 2406.0007 | C12: ='Revenue & Pricing'!C25 -> 4845.4182 | D12: ='Revenue & Pricing'!D25 -> 10902.191
A13: Monthly profit at target utilisation | B13: =B12-B5 -> -3631.9993 | C13: =C12-C5 -> -1888.5263 | D13: =D12-D5 -> 688.38529
A14: Gross margin at target utilisation | B14: =IF(B12=0,0,B13/B12) -> -1.5095587 | C14: =IF(C12=0,0,C13/C12) -> -0.38975507 | D14: =IF(D12=0,0,D13/D12) -> 0.063141923
A15: Total startup cost | B15: ='Startup Costs'!B26 -> 112448 | C15: ='Startup Costs'!C26 -> 158741.33 | D15: ='Startup Costs'!D26 -> 255994.67
A16: Payback period (months, at target) | B16: =IF(B13<=0,"never",B15/B13) -> never | C16: =IF(C13<=0,"never",C15/C13) -> never | D16: =IF(D13<=0,"never",D15/D13) -> 371.87701 | E16: From startup cost, once at target utilisation.
A18: SENSITIVITY - what ARPU do you actually need?
A19: Required ARPU to break even at target util | B19: =IF(B10*Assumptions!$B$47=0,0,B5/(B10*Assumptions!$B$47)/(1-Assumptions!$B$44-Assumptions!$B$45-Assumptions!$B$46)) -> 71.6479 | C19: =IF(C10*Assumptions!$B$47=0,0,C5/(C10*Assumptions!$B$47)/(1-Assumptions!$B$44-Assumptions!$B$45-Assumptions!$B$46)) -> 39.677507 | D19: =IF(D10*Assumptions!$B$47=0,0,D5/(D10*Assumptions!$B$47)/(1-Assumptions!$B$44-Assumptions!$B$45-Assumptions!$B$46)) -> 26.747298 | E19: Fully-loaded cost divided by VMs at target utilisation.
A20: Required ARPU to break even at 100% sellable | B20: =IF(B10=0,0,B5/B10/(1-Assumptions!$B$44-Assumptions!$B$45-Assumptions!$B$46)) -> 53.735925 | C20: =IF(C10=0,0,C5/C10/(1-Assumptions!$B$44-Assumptions!$B$45-Assumptions!$B$46)) -> 29.75813 | D20: =IF(D10=0,0,D5/D10/(1-Assumptions!$B$44-Assumptions!$B$45-Assumptions!$B$46)) -> 20.060474 | E20: The floor. If your plan prices are below this you cannot ever break even.
A21: Current ARPU | B21: =Capacity!$B$24 -> 28.55 | C21: =Capacity!$B$24 -> 28.55 | D21: =Capacity!$B$24 -> 28.55 | E21: From the plan mix.
A22: Price increase needed at target util | B22: =IF(B21=0,0,B19/B21-1) -> 1.5095587 | C22: =IF(C21=0,0,C19/C21-1) -> 0.38975507 | D22: =IF(D21=0,0,D19/D21-1) -> -0.063141923 | E22: Negative means you already clear break-even at target utilisation.
A24: INTERPRETATION
A25: Break-even above 60% of sellable capacity means your pricing is too low or your cost base too high.
A26: You will never comfortably fill a cluster, and any churn puts you underwater.
A27: Levers, in order of effect: raise prices, reduce IPv4 cost, buy more RAM per node, cut DDoS/transit spend.
A28: Note that 'never' in payback means the scenario loses money at target utilisation - fix the inputs.

Sheet Scenarios
A1: Scenario Comparison: 3 / 5 / 10 nodes
A3: Metric | B3: 3 nodes | C3: 5 nodes | D3: 10 nodes | E3: Comment
A4: Total startup cost | B4: ='Startup Costs'!B26 -> 112448 | C4: ='Startup Costs'!C26 -> 158741.33 | D4: ='Startup Costs'!D26 -> 255994.67
A5: Cash opex / month | B5: ='Monthly Opex'!B25 -> 4413 | C5: ='Monthly Opex'!C25 -> 4477 | D5: ='Monthly Opex'!D25 -> 6377
A6: Fully-loaded cost / month | B6: ='Monthly Opex'!B26 -> 6038 | C6: ='Monthly Opex'!C26 -> 6733.9444 | D6: ='Monthly Opex'!D26 -> 10213.806
A7: Sellable VM capacity | B7: ='Revenue & Pricing'!B18 -> 118.15385 | C7: ='Revenue & Pricing'!C18 -> 237.94872 | D7: ='Revenue & Pricing'!D18 -> 535.38462 | E7: After N+1 reserve
A8: Net revenue at target util | B8: ='Revenue & Pricing'!B25 -> 2406.0007 | C8: ='Revenue & Pricing'!C25 -> 4845.4182 | D8: ='Revenue & Pricing'!D25 -> 10902.191
A9: Break-even VMs (fully loaded) | B9: ='Break-Even'!B9 -> 222.38551 | C9: ='Break-Even'!C9 -> 248.01783 | D9: ='Break-Even'!D9 -> 376.18455
A10: Break-even % of capacity | B10: ='Break-Even'!B11 -> 1.882169 | C10: ='Break-Even'!C11 -> 1.0423163 | D10: ='Break-Even'!D11 -> 0.70264356 | E10: Target below 60%
A11: Monthly profit at target | B11: ='Break-Even'!B13 -> -3631.9993 | C11: ='Break-Even'!C13 -> -1888.5263 | D11: ='Break-Even'!D13 -> 688.38529
A12: Gross margin at target | B12: ='Break-Even'!B14 -> -1.5095587 | C12: ='Break-Even'!C14 -> -0.38975507 | D12: ='Break-Even'!D14 -> 0.063141923
A13: Payback (months) | B13: ='Break-Even'!B16 -> never | C13: ='Break-Even'!C16 -> never | D13: ='Break-Even'!D16 -> 371.87701
A15: QUALITATIVE DIFFERENCES (not in the numbers)
A16: Aspect | B16: 3 nodes | C16: 5 nodes | D16: 10 nodes | E16: Note
A17: Ceph self-healing | B17: No | C17: Yes | D17: Yes | E17: 3 nodes cannot rebuild a lost replica - no 4th host
A18: Rolling maintenance | B18: Degraded | C18: Clean | D18: Clean | E18: 5+ nodes allows non-disruptive node work
A19: Ceph safety factor | B19: 60% | C19: 70% | D19: 75% | E19: How full you can safely run
A20: Defensible SLA | B20: 99.5-99.9% | C20: 99.9-99.95% | D20: 99.95% | E20: Derive from your own measured RTO
A21: Rack failure domains | B21: No | C21: No | D21: Possible | E21: Needs 3+ racks for size=3
A22: Operational headroom | B22: Tight | C22: Comfortable | D22: Good
A24: KEY CONCLUSION
A25: 3 to 4 nodes is a QUALITATIVE change, not a quantitative one: it introduces Ceph self-healing.
A26: It is the highest-return infrastructure purchase you will make. Order it at 55% raw utilisation,
A27: not when you are full - hardware lead time plus rebalance time means 'when full' is too late.

Sheet Cash Flow 24mo
A1: 24-Month Cash Flow - 3 node cluster
A2: Edit the blue ramp row. Revenue arrives monthly; capex is spent up front. This is where founders get caught.
A4: Month | B4: 1 | C4: 2 | D4: 3 | E4: 4 | F4: 5 | G4: 6 | H4: 7 | I4: 8 | J4: 9 | K4: 10 | L4: 11 | M4: 12 | N4: 13 | O4: 14 | P4: 15 | Q4: 16 | R4: 17 | S4: 18 | T4: 19 | U4: 20 | V4: 21 | W4: 22 | X4: 23 | Y4: 24
A5: Net new VMs (input) | B5: 0 | C5: 0 | D5: 0 | E5: 2 | F5: 4 | G5: 6 | H5: 8 | I5: 9 | J5: 10 | K5: 11 | L5: 12 | M5: 12 | N5: 12 | O5: 12 | P5: 11 | Q5: 11 | R5: 10 | S5: 10 | T5: 10 | U5: 9 | V5: 9 | W5: 9 | X5: 8 | Y5: 8
A6: Churned VMs | B6: 0 | C6: =-B7*Assumptions!$B$48 -> 0 | D6: =-C7*Assumptions!$B$48 -> 0 | E6: =-D7*Assumptions!$B$48 -> 0 | F6: =-E7*Assumptions!$B$48 -> -0.07 | G6: =-F7*Assumptions!$B$48 -> -0.20755 | H6: =-G7*Assumptions!$B$48 -> -0.41028575 | I6: =-H7*Assumptions!$B$48 -> -0.67592575 | J6: =-I7*Assumptions!$B$48 -> -0.96726835 | ... Y6: =-X7*Assumptions!$B$48 -> -4.807242
A7: Active VMs (cumulative) | B7: =B5+B6 -> 0 | C7: =B7+C5+C6 -> 0 | D7: =C7+D5+D6 -> 0 | E7: =D7+E5+E6 -> 2 | F7: =E7+F5+F6 -> 5.93 | G7: =F7+G5+G6 -> 11.72245 | H7: =G7+H5+H6 -> 19.312164 | I7: =H7+I5+I6 -> 27.636239 | J7: =I7+J5+J6 -> 36.66897 | ... Y7: =X7+Y5+Y6 -> 140.54253
A9: Gross revenue | B9: =B7*Capacity!$B$24 -> 0 | C9: =C7*Capacity!$B$24 -> 0 | D9: =D7*Capacity!$B$24 -> 0 | E9: =E7*Capacity!$B$24 -> 57.1 | F9: =F7*Capacity!$B$24 -> 169.3015 | G9: =G7*Capacity!$B$24 -> 334.67595 | H9: =H7*Capacity!$B$24 -> 551.36229 | I9: =I7*Capacity!$B$24 -> 789.01461 | ... Y9: =Y7*Capacity!$B$24 -> 4012.4892
A10: Revenue deductions | B10: =-B9*(Assumptions!$B$44+Assumptions!$B$45+Assumptions!$B$46) -> 0 | C10: =-C9*(Assumptions!$B$44+Assumptions!$B$45+Assumptions!$B$46) -> 0 | D10: =-D9*(Assumptions!$B$44+Assumptions!$B$45+Assumptions!$B$46) -> 0 | E10: =-E9*(Assumptions!$B$44+Assumptions!$B$45+Assumptions!$B$46) -> -2.7979 | F10: =-F9*(Assumptions!$B$44+Assumptions!$B$45+Assumptions!$B$46) -> -8.2957735 | G10: =-G9*(Assumptions!$B$44+Assumptions!$B$45+Assumptions!$B$46) -> -16.399121 | H10: =-H9*(Assumptions!$B$44+Assumptions!$B$45+Assumptions!$B$46) -> -27.016752 | I10: =-I9*(Assumptions!$B$44+Assumptions!$B$45+Assumptions!$B$46) -> -38.661716 | ... Y10: =-Y9*(Assumptions!$B$44+Assumptions!$B$45+Assumptions!$B$46) -> -196.61197
A11: Net revenue | B11: =B9+B10 -> 0 | C11: =C9+C10 -> 0 | D11: =D9+D10 -> 0 | E11: =E9+E10 -> 54.3021 | F11: =F9+F10 -> 161.00573 | G11: =G9+G10 -> 318.27683 | H11: =H9+H10 -> 524.34554 | I11: =I9+I10 -> 750.35289 | ... Y11: =Y9+Y10 -> 3815.8772
A12: Cash opex | B12: =-'Monthly Opex'!$B$25 -> -4413 | C12: =-'Monthly Opex'!$B$25 -> -4413 | D12: =-'Monthly Opex'!$B$25 -> -4413 | E12: =-'Monthly Opex'!$B$25 -> -4413 | F12: =-'Monthly Opex'!$B$25 -> -4413 | G12: =-'Monthly Opex'!$B$25 -> -4413 | H12: =-'Monthly Opex'!$B$25 -> -4413 | I12: =-'Monthly Opex'!$B$25 -> -4413 | ... Y12: =-'Monthly Opex'!$B$25 -> -4413
A13: Capex (month 1) | B13: =-'Startup Costs'!$B$26 -> -112448 | C13: 0 | D13: 0 | E13: 0 | F13: 0 | G13: 0 | H13: 0 | I13: 0 | J13: 0 | K13: 0 | L13: 0 | M13: 0 | N13: 0 | O13: 0 | P13: 0 | Q13: 0 | R13: 0 | S13: 0 | T13: 0 | U13: 0 | V13: 0 | W13: 0 | X13: 0 | Y13: 0
A14: Monthly net cash flow | B14: =B11+B12+B13 -> -116861 | C14: =C11+C12+C13 -> -4413 | D14: =D11+D12+D13 -> -4413 | E14: =E11+E12+E13 -> -4358.6979 | F14: =F11+F12+F13 -> -4251.9943 | G14: =G11+G12+G13 -> -4094.7232 | H14: =H11+H12+H13 -> -3888.6545 | I14: =I11+I12+I13 -> -3662.6471 | ... Y14: =Y11+Y12+Y13 -> -597.12279
A15: Cumulative cash position | B15: =B14 -> -116861 | C15: =B15+C14 -> -121274 | D15: =C15+D14 -> -125687 | E15: =D15+E14 -> -130045.7 | F15: =E15+F14 -> -134297.69 | G15: =F15+G14 -> -138392.42 | H15: =G15+H14 -> -142281.07 | I15: =H15+I14 -> -145943.72 | J15: =I15+J14 -> -149361.12 | ... Y15: =X15+Y14 -> -173850.54
A18: SUMMARY
A19: Peak cash requirement | B19: =-MIN(B15:Y15) -> 173850.54 | D19: The capital you must have available. Add margin.
A20: Active VMs at month 24 | B20: =Y7 -> 140.54253
A21: Net revenue at month 24 | B21: =Y11 -> 3815.8772
A22: Monthly cash flow at month 24 | B22: =Y14 -> -597.12279
A23: Cash position at month 24 | B23: =Y15 -> -173850.54 | D23: Negative means you have not recovered startup cost yet.
A24: Break-even VMs (fully loaded) | B24: ='Break-Even'!B9 -> 222.38551
A26: NOTE: hardware capex hits in month 1 while revenue ramps over two years.
A27: The 'peak cash requirement' figure above is the number that determines whether this plan is viable for you.
A28: Model 18 months of runway, not 6. Revenue ramps slower than every founder expects.

Sheet Viable Config
A1: Viable Configuration - all three levers moved together
A2: The baseline scenario does not break even. This sheet models the corrected fix.
A4: WHY 'JUST BUY MORE RAM' DOES NOT WORK
A5: Baseline VMs/node by resource (3 nodes):
A6: RAM bound (512GB) | B6: 59.5 | E6: Nearly tied with disk.
A7: vCPU bound (128 threads @ 3.5x) | B7: 114.9 | E7: Plenty of headroom.
A8: Disk bound (6x7.68TB, safety 0.60) | B8: 59.1 | E8: BINDS - marginally below RAM.
A9: If you ONLY double RAM to 1TB: | B9: 59.1 | E9: Disk still binds at 59.1. Gain is ZERO. RAM alone is not the lever.
A11: Correct fix: move RAM, DISK, and PRICE together. Then vCPU becomes the binding resource.
A13: ALTERNATIVE ASSUMPTIONS - edit these (blue/yellow)
A14: Assumption | B14: Value | C14: Unit | E14: Rationale
A15: Node cost (prior-gen platform) | B15: 16000 | C15: $ | E15: Prior-generation/refurbished platform, 1TB RAM, 6x15.36TB NVMe. More than baseline because the drives are larger.
A16: Installed RAM per node | B16: 1024 | C16: GB | E16: Doubled. Necessary but NOT sufficient on its own.
A17: Reserved RAM per node | B17: 56 | C17: GB | E17: Slightly higher than baseline: more OSD capacity to manage.
A18: CPU threads per node | B18: 128 | C18: threads | E18: Unchanged.
A19: NVMe drives per node | B19: 6 | C19: drives | E19: Unchanged count.
A20: Raw TB per drive | B20: 15.36 | C20: TB | E20: DOUBLED from 7.68TB. This is the lever that actually unblocks density.
A21: Thin provisioning ratio | B21: 1.5 | C21: x | E21: Sold disk vs actual consumption. Monitor real usage; above 2x is gambling.
A22: Switches (refurbished pair) | B22: 5000 | C22: $ | E22: Prior-generation refurbished 25GbE pair.
A23: Border routers | B23: 3000 | C23: $ | E23: Software routing on x86 with FRR/VyOS.
A24: Other hardware (PBS, misc, spares, monitoring) | B24: 18000 | C24: $ | E24: PBS 9000 + rails/cables 3500 + spares 3000 + monitoring host 2500.
A25: Setup and professional costs | B25: 22400 | C25: $ | E25: Legal, formation, LIR, colo/xconn setup, plus one IPv4 /24 purchase.
A26: Contingency | B26: 0.12 | C26: % of capex | E26: Do not set below 10%.
A27: Cash opex per month (3 nodes) | B27: 4413 | C27: $/mo | E27: Same as baseline. DDoS scrubbing KEPT - dropping it saves ~700/mo but costs you the ability to keep an attacked customer online.
A28: Depreciation life | B28: 48 | C28: months
A29: vCPU overcommit ratio | B29: 3.5 | C29: x | E29: Unchanged. Monitor CPU steal time.
A30: Target utilisation | B30: 0.75 | C30: % | E30: Unchanged.
A31: Revenue deductions (processing+baddebt+SLA) | B31: 0.049 | C31: % | E31: Same as baseline: 2.9% + 1.5% + 0.5%.
A33: PREMIUM PLAN PRICING - the third lever
A34: Plan | B34: Weight | C34: vCPU | D34: RAM GB | E34: Disk GB | F34: Premium price | G34: Baseline
A35: S1 | B35: 0.2 | C35: 1 | D35: 2 | E35: 40 | F35: 18 | G35: baseline was $8
A36: S2 | B36: 0.35 | C36: 2 | D36: 4 | E36: 80 | F36: 34 | G36: baseline was $15
A37: S4 | B37: 0.25 | C37: 4 | D37: 8 | E37: 160 | F37: 65 | G37: baseline was $29
A38: S8 | B38: 0.15 | C38: 8 | D38: 16 | E38: 320 | F38: 128 | G38: baseline was $58
A39: S16 | B39: 0.05 | C39: 16 | D39: 32 | E39: 640 | F39: 255 | G39: baseline was $115
A40: Weighted average | B40: =SUM(B35:B39) -> 1 | C40: =SUMPRODUCT($B$35:$B$39,C35:C39)/$B$40 -> 3.9 | D40: =SUMPRODUCT($B$35:$B$39,D35:D39)/$B$40 -> 7.8 | E40: =SUMPRODUCT($B$35:$B$39,E35:E39)/$B$40 -> 156 | F40: =SUMPRODUCT($B$35:$B$39,F35:F39)/$B$40 -> 63.7
A42: CAPACITY PER NODE
A43: Metric | B43: 3 nodes | C43: 5 nodes | D43: 10 nodes | E43: Note
A44: Node count | B44: 3 | C44: 5 | D44: 10
A45: Ceph safety factor | B45: 0.6 | C45: 0.7 | D45: 0.75 | E45: Larger clusters run fuller.
...
